Workbook

Sheet 人员资源情况
A1: 开始时间 | B1: 结束时间 | C1: 人员 | D1: 工时
A2: 46220 | B2: 46234 | C2: @魏殷浩(80019157) | D2: =任务计划表!F1

Sheet 任务计划表
F1: =SUM(W4:W75)/(人员资源情况!B2-人员资源情况!A2)
F2: 项目 | G2: 开始时间 | H2: 结束时间 | I2: 项目描述 | J2: 资源描述
J3: 资源类型 | K3: 资源名称 | L3: 资源开始时间 | M3: 资源结束时间 | N3: 日平均工时投入 （h）
E4: 巴西经营中心 | F4: 巴西NB-V3 | G4: / | H4: 46318 | I4: TR4A-测试阶段 | J4: 项目经理 | K4: @项家祺(80004213)(项家祺) | L4: / | M4: 46318 | N4: 1 | O4: =任务计划表!K4 | P4: =IF(IF(任务计划表!L4="/",人员资源情况!$A$2,L4)>M4,M4,(IF(任务计划表!L4="/",人员资源情况!$A$2,L4))) | Q4: =IF(M4="/",人员资源情况!$B$2,任务计划表!M4) | R4: =任务计划表!N4 | S4: =IF(O4=人员资源情况!C$2,1,0) | T4: =IF(P4>=人员资源情况!A$2,1,0) | U4: =IF(Q4<=人员资源情况!B$2,1,0) | V4: =IF(T4*U4,Q4-P4,IF(T4>U4,人员资源情况!B$2-P4,IF(T4<U4,任务计划表!Q4-人员资源情况!A$2,0)))*R4*S4 | W4: =IF(V4<0,0,V4)
E5: 巴西经营中心 | J5: 固件设计文档 | K5: @项家祺(80004213)(项家祺) | L5: / | M5: 46233 | N5: 4 | O5: =任务计划表!K5 | P5: =IF(IF(任务计划表!L5="/",人员资源情况!$A$2,L5)>M5,M5,(IF(任务计划表!L5="/",人员资源情况!$A$2,L5))) | Q5: =IF(M5="/",人员资源情况!$B$2,任务计划表!M5) | R5: =任务计划表!N5 | S5: =IF(O5=人员资源情况!C$2,1,0) | T5: =IF(P5>=人员资源情况!A$2,1,0) | U5: =IF(Q5<=人员资源情况!B$2,1,0) | V5: =IF(T5*U5,Q5-P5,IF(T5>U5,人员资源情况!B$2-P5,IF(T5<U5,任务计划表!Q5-人员资源情况!A$2,0)))*R5*S5 | W5: =IF(V5<0,0,V5)
E6: 巴西经营中心 | J6: 固件工程师 | K6: @袁琮欣(80015786)(袁琮欣) | L6: / | M6: 46288 | N6: 8 | O6: =任务计划表!K6 | P6: =IF(IF(任务计划表!L6="/",人员资源情况!$A$2,L6)>M6,M6,(IF(任务计划表!L6="/",人员资源情况!$A$2,L6))) | Q6: =IF(M6="/",人员资源情况!$B$2,任务计划表!M6) | R6: =任务计划表!N6 | S6: =IF(O6=人员资源情况!C$2,1,0) | T6: =IF(P6>=人员资源情况!A$2,1,0) | U6: =IF(Q6<=人员资源情况!B$2,1,0) | V6: =IF(T6*U6,Q6-P6,IF(T6>U6,人员资源情况!B$2-P6,IF(T6<U6,任务计划表!Q6-人员资源情况!A$2,0)))*R6*S6 | W6: =IF(V6<0,0,V6)
E7: 巴西经营中心 | J7: 固件工程师 | K7: @李昊龙(80016809) | L7: / | M7: 46288 | N7: 8 | O7: =任务计划表!K7 | P7: =IF(IF(任务计划表!L7="/",人员资源情况!$A$2,L7)>M7,M7,(IF(任务计划表!L7="/",人员资源情况!$A$2,L7))) | Q7: =IF(M7="/",人员资源情况!$B$2,任务计划表!M7) | R7: =任务计划表!N7 | S7: =IF(O7=人员资源情况!C$2,1,0) | T7: =IF(P7>=人员资源情况!A$2,1,0) | U7: =IF(Q7<=人员资源情况!B$2,1,0) | V7: =IF(T7*U7,Q7-P7,IF(T7>U7,人员资源情况!B$2-P7,IF(T7<U7,任务计划表!Q7-人员资源情况!A$2,0)))*R7*S7 | W7: =IF(V7<0,0,V7)
E8: 巴西经营中心 | J8: 固件工程师-L660测试/BC680 | K8: @袁琮欣(80015786)(袁琮欣) | L8: 46218 | M8: 46221 | N8: 0.5 | O8: =任务计划表!K8 | P8: =IF(IF(任务计划表!L8="/",人员资源情况!$A$2,L8)>M8,M8,(IF(任务计划表!L8="/",人员资源情况!$A$2,L8))) | Q8: =IF(M8="/",人员资源情况!$B$2,任务计划表!M8) | R8: =任务计划表!N8 | S8: =IF(O8=人员资源情况!C$2,1,0) | T8: =IF(P8>=人员资源情况!A$2,1,0) | U8: =IF(Q8<=人员资源情况!B$2,1,0) | V8: =IF(T8*U8,Q8-P8,IF(T8>U8,人员资源情况!B$2-P8,IF(T8<U8,任务计划表!Q8-人员资源情况!A$2,0)))*R8*S8 | W8: =IF(V8<0,0,V8)
E9: 巴西经营中心 | J9: 硬件工程师-PCB调整 | K9: @童景顺(80004217)(童景顺) | L9: / | M9: / | N9: 1 | O9: =任务计划表!K9 | P9: =IF(IF(任务计划表!L9="/",人员资源情况!$A$2,L9)>M9,M9,(IF(任务计划表!L9="/",人员资源情况!$A$2,L9))) | Q9: =IF(M9="/",人员资源情况!$B$2,任务计划表!M9) | R9: =任务计划表!N9 | S9: =IF(O9=人员资源情况!C$2,1,0) | T9: =IF(P9>=人员资源情况!A$2,1,0) | U9: =IF(Q9<=人员资源情况!B$2,1,0) | V9: =IF(T9*U9,Q9-P9,IF(T9>U9,人员资源情况!B$2-P9,IF(T9<U9,任务计划表!Q9-人员资源情况!A$2,0)))*R9*S9 | W9: =IF(V9<0,0,V9)
E10: 巴西经营中心 | F10: 巴西NB-V3.1预研 | J10: 固件工程师-三轴传感器预研 | K10: @张国庆(80019159) | L10: 46223 | M10: 46237 | N10: 4 | O10: =任务计划表!K10 | P10: =IF(IF(任务计划表!L10="/",人员资源情况!$A$2,L10)>M10,M10,(IF(任务计划表!L10="/",人员资源情况!$A$2,L10))) | Q10: =IF(M10="/",人员资源情况!$B$2,任务计划表!M10) | R10: =任务计划表!N10 | S10: =IF(O10=人员资源情况!C$2,1,0) | T10: =IF(P10>=人员资源情况!A$2,1,0) | U10: =IF(Q10<=人员资源情况!B$2,1,0) | V10: =IF(T10*U10,Q10-P10,IF(T10>U10,人员资源情况!B$2-P10,IF(T10<U10,任务计划表!Q10-人员资源情况!A$2,0)))*R10*S10 | W10: =IF(V10<0,0,V10)
E11: 巴西经营中心 | F11: 巴西脉冲-V3 | J11: 项目经理 | K11: @项家祺(80004213)(项家祺) | L11: / | M11: 46318 | N11: 1 | O11: =任务计划表!K11 | P11: =IF(IF(任务计划表!L11="/",人员资源情况!$A$2,L11)>M11,M11,(IF(任务计划表!L11="/",人员资源情况!$A$2,L11))) | Q11: =IF(M11="/",人员资源情况!$B$2,任务计划表!M11) | R11: =任务计划表!N11 | S11: =IF(O11=人员资源情况!C$2,1,0) | T11: =IF(P11>=人员资源情况!A$2,1,0) | U11: =IF(Q11<=人员资源情况!B$2,1,0) | V11: =IF(T11*U11,Q11-P11,IF(T11>U11,人员资源情况!B$2-P11,IF(T11<U11,任务计划表!Q11-人员资源情况!A$2,0)))*R11*S11 | W11: =IF(V11<0,0,V11)
E12: 巴西经营中心 | F12: 巴西脉冲-V3 | J12: 硬件工程师 | K12: @童景顺(80004217)(童景顺) | N12: 7 | O12: =任务计划表!K12 | P12: =IF(IF(任务计划表!L12="/",人员资源情况!$A$2,L12)>M12,M12,(IF(任务计划表!L12="/",人员资源情况!$A$2,L12))) | Q12: =IF(M12="/",人员资源情况!$B$2,任务计划表!M12) | R12: =任务计划表!N12 | S12: =IF(O12=人员资源情况!C$2,1,0) | T12: =IF(P12>=人员资源情况!A$2,1,0) | U12: =IF(Q12<=人员资源情况!B$2,1,0) | V12: =IF(T12*U12,Q12-P12,IF(T12>U12,人员资源情况!B$2-P12,IF(T12<U12,任务计划表!Q12-人员资源情况!A$2,0)))*R12*S12 | W12: =IF(V12<0,0,V12)
E13: 巴西经营中心 | F13: 巴西脉冲-V3 | J13: SE设计 | K13: @项家祺(80004213)(项家祺) | L13: / | M13: 46233 | N13: 4 | O13: =任务计划表!K13 | P13: =IF(IF(任务计划表!L13="/",人员资源情况!$A$2,L13)>M13,M13,(IF(任务计划表!L13="/",人员资源情况!$A$2,L13))) | Q13: =IF(M13="/",人员资源情况!$B$2,任务计划表!M13) | R13: =任务计划表!N13 | S13: =IF(O13=人员资源情况!C$2,1,0) | T13: =IF(P13>=人员资源情况!A$2,1,0) | U13: =IF(Q13<=人员资源情况!B$2,1,0) | V13: =IF(T13*U13,Q13-P13,IF(T13>U13,人员资源情况!B$2-P13,IF(T13<U13,任务计划表!Q13-人员资源情况!A$2,0)))*R13*S13 | W13: =IF(V13<0,0,V13)
E14: 巴西经营中心 | F14: 巴西脉冲-V3 | J14: 固件工程师-开发 | K14: 朱葵阳 | L14: 1900-01-01 | M14: 2026-07-30 | N14: 8 | O14: =任务计划表!K14 | P14: =IF(IF(任务计划表!L14="/",人员资源情况!$A$2,L14)>M14,M14,(IF(任务计划表!L14="/",人员资源情况!$A$2,L14))) | Q14: =IF(M14="/",人员资源情况!$B$2,任务计划表!M14) | R14: =任务计划表!N14 | S14: =IF(O14=人员资源情况!C$2,1,0) | T14: =IF(P14>=人员资源情况!A$2,1,0) | U14: =IF(Q14<=人员资源情况!B$2,1,0) | V14: =IF(T14*U14,Q14-P14,IF(T14>U14,人员资源情况!B$2-P14,IF(T14<U14,任务计划表!Q14-人员资源情况!A$2,0)))*R14*S14 | W14: =IF(V14<0,0,V14)
E15: 巴西经营中心 | F15: 巴西脉冲-V3 | J15: 固件工程师-认证跟踪 | K15: @朱葵阳(80019092)(朱葵阳) | L15: 46225 | M15: 46288 | N15: 1.5 | O15: =任务计划表!K15 | P15: =IF(IF(任务计划表!L15="/",人员资源情况!$A$2,L15)>M15,M15,(IF(任务计划表!L15="/",人员资源情况!$A$2,L15))) | Q15: =IF(M15="/",人员资源情况!$B$2,任务计划表!M15) | R15: =任务计划表!N15 | S15: =IF(O15=人员资源情况!C$2,1,0) | T15: =IF(P15>=人员资源情况!A$2,1,0) | U15: =IF(Q15<=人员资源情况!B$2,1,0) | V15: =IF(T15*U15,Q15-P15,IF(T15>U15,人员资源情况!B$2-P15,IF(T15<U15,任务计划表!Q15-人员资源情况!A$2,0)))*R15*S15 | W15: =IF(V15<0,0,V15)
E16: 巴西经营中心 | F16: 巴西脉冲-V3 | J16: 硬件工程师-PCB调整 | K16: @童景顺(80004217)(童景顺) | O16: =任务计划表!K16 | P16: =IF(IF(任务计划表!L16="/",人员资源情况!$A$2,L16)>M16,M16,(IF(任务计划表!L16="/",人员资源情况!$A$2,L16))) | Q16: =IF(M16="/",人员资源情况!$B$2,任务计划表!M16) | R16: =任务计划表!N16 | S16: =IF(O16=人员资源情况!C$2,1,0) | T16: =IF(P16>=人员资源情况!A$2,1,0) | U16: =IF(Q16<=人员资源情况!B$2,1,0) | V16: =IF(T16*U16,Q16-P16,IF(T16>U16,人员资源情况!B$2-P16,IF(T16<U16,任务计划表!Q16-人员资源情况!A$2,0)))*R16*S16 | W16: =IF(V16<0,0,V16)
E17: 巴西经营中心 | F17: 巴西WMBUS-walkby | J17: 项目经理 | K17: @项家祺(80004213)(项家祺) | L17: / | M17: / | N17: 0.5 | O17: =任务计划表!K17 | P17: =IF(IF(任务计划表!L17="/",人员资源情况!$A$2,L17)>M17,M17,(IF(任务计划表!L17="/",人员资源情况!$A$2,L17))) | Q17: =IF(M17="/",人员资源情况!$B$2,任务计划表!M17) | R17: =任务计划表!N17 | S17: =IF(O17=人员资源情况!C$2,1,0) | T17: =IF(P17>=人员资源情况!A$2,1,0) | U17: =IF(Q17<=人员资源情况!B$2,1,0) | V17: =IF(T17*U17,Q17-P17,IF(T17>U17,人员资源情况!B$2-P17,IF(T17<U17,任务计划表!Q17-人员资源情况!A$2,0)))*R17*S17 | W17: =IF(V17<0,0,V17)
E18: 巴西经营中心 | J18: SE设计 | K18: @项家祺(80004213)(项家祺) | L18: / | M18: 46233 | N18: 4 | O18: =任务计划表!K18 | P18: =IF(IF(任务计划表!L18="/",人员资源情况!$A$2,L18)>M18,M18,(IF(任务计划表!L18="/",人员资源情况!$A$2,L18))) | Q18: =IF(M18="/",人员资源情况!$B$2,任务计划表!M18) | R18: =任务计划表!N18 | S18: =IF(O18=人员资源情况!C$2,1,0) | T18: =IF(P18>=人员资源情况!A$2,1,0) | U18: =IF(Q18<=人员资源情况!B$2,1,0) | V18: =IF(T18*U18,Q18-P18,IF(T18>U18,人员资源情况!B$2-P18,IF(T18<U18,任务计划表!Q18-人员资源情况!A$2,0)))*R18*S18 | W18: =IF(V18<0,0,V18)
E19: 巴西经营中心 | J19: 固件工程师-调试样机 | K19: @毛文豪(80018842) | L19: 46205 | M19: 2026-08-05 | N19: 1 | O19: =任务计划表!K19 | P19: =IF(IF(任务计划表!L19="/",人员资源情况!$A$2,L19)>M19,M19,(IF(任务计划表!L19="/",人员资源情况!$A$2,L19))) | Q19: =IF(M19="/",人员资源情况!$B$2,任务计划表!M19) | R19: =任务计划表!N19 | S19: =IF(O19=人员资源情况!C$2,1,0) | T19: =IF(P19>=人员资源情况!A$2,1,0) | U19: =IF(Q19<=人员资源情况!B$2,1,0) | V19: =IF(T19*U19,Q19-P19,IF(T19>U19,人员资源情况!B$2-P19,IF(T19<U19,任务计划表!Q19-人员资源情况!A$2,0)))*R19*S19 | W19: =IF(V19<0,0,V19)
E20: 巴西经营中心 | J20: 固件工程师-开发设计 | K20: @朱葵阳(80019092)(朱葵阳) | L20: 46220 | M20: 46247 | N20: 6 | O20: =任务计划表!K20 | P20: =IF(IF(任务计划表!L20="/",人员资源情况!$A$2,L20)>M20,M20,(IF(任务计划表!L20="/",人员资源情况!$A$2,L20))) | Q20: =IF(M20="/",人员资源情况!$B$2,任务计划表!M20) | R20: =任务计划表!N20 | S20: =IF(O20=人员资源情况!C$2,1,0) | T20: =IF(P20>=人员资源情况!A$2,1,0) | U20: =IF(Q20<=人员资源情况!B$2,1,0) | V20: =IF(T20*U20,Q20-P20,IF(T20>U20,人员资源情况!B$2-P20,IF(T20<U20,任务计划表!Q20-人员资源情况!A$2,0)))*R20*S20 | W20: =IF(V20<0,0,V20)
B21: 已删除 | E21: 巴西经营中心 | J21: 固件工程师-开发设计 | K21: @毛文豪(80018842) | L21: 46230 | M21: 46249 | N21: 6 | O21: =任务计划表!K21 | P21: =IF(IF(任务计划表!L21="/",人员资源情况!$A$2,L21)>M21,M21,(IF(任务计划表!L21="/",人员资源情况!$A$2,L21))) | Q21: =IF(M21="/",人员资源情况!$B$2,任务计划表!M21) | R21: =任务计划表!N21 | S21: =IF(O21=人员资源情况!C$2,1,0) | T21: =IF(P21>=人员资源情况!A$2,1,0) | U21: =IF(Q21<=人员资源情况!B$2,1,0) | V21: =IF(T21*U21,Q21-P21,IF(T21>U21,人员资源情况!B$2-P21,IF(T21<U21,任务计划表!Q21-人员资源情况!A$2,0)))*R21*S21 | W21: =IF(V21<0,0,V21)
E22: 巴西经营中心 | J22: 硬件工程师-PCB调整 | K22: @童景顺(80004217)(童景顺) | N22: 7 | O22: =任务计划表!K22 | P22: =IF(IF(任务计划表!L22="/",人员资源情况!$A$2,L22)>M22,M22,(IF(任务计划表!L22="/",人员资源情况!$A$2,L22))) | Q22: =IF(M22="/",人员资源情况!$B$2,任务计划表!M22) | R22: =任务计划表!N22 | S22: =IF(O22=人员资源情况!C$2,1,0) | T22: =IF(P22>=人员资源情况!A$2,1,0) | U22: =IF(Q22<=人员资源情况!B$2,1,0) | V22: =IF(T22*U22,Q22-P22,IF(T22>U22,人员资源情况!B$2-P22,IF(T22<U22,任务计划表!Q22-人员资源情况!A$2,0)))*R22*S22 | W22: =IF(V22<0,0,V22)
E23: 巴西经营中心 | J23: 固件工程师-测试跟踪 | K23: @朱葵阳(80019092)(朱葵阳) | L23: 46249 | M23: 46300 | N23: 2 | O23: =任务计划表!K23 | P23: =IF(IF(任务计划表!L23="/",人员资源情况!$A$2,L23)>M23,M23,(IF(任务计划表!L23="/",人员资源情况!$A$2,L23))) | Q23: =IF(M23="/",人员资源情况!$B$2,任务计划表!M23) | R23: =任务计划表!N23 | S23: =IF(O23=人员资源情况!C$2,1,0) | T23: =IF(P23>=人员资源情况!A$2,1,0) | U23: =IF(Q23<=人员资源情况!B$2,1,0) | V23: =IF(T23*U23,Q23-P23,IF(T23>U23,人员资源情况!B$2-P23,IF(T23<U23,任务计划表!Q23-人员资源情况!A$2,0)))*R23*S23 | W23: =IF(V23<0,0,V23)
E24: 巴西经营中心 | J24: 固件工程师-认证跟踪 | K24: @朱葵阳(80019092)(朱葵阳) | L24: 46300 | M24: 46360 | N24: 1 | O24: =任务计划表!K24 | P24: =IF(IF(任务计划表!L24="/",人员资源情况!$A$2,L24)>M24,M24,(IF(任务计划表!L24="/",人员资源情况!$A$2,L24))) | Q24: =IF(M24="/",人员资源情况!$B$2,任务计划表!M24) | R24: =任务计划表!N24 | S24: =IF(O24=人员资源情况!C$2,1,0) | T24: =IF(P24>=人员资源情况!A$2,1,0) | U24: =IF(Q24<=人员资源情况!B$2,1,0) | V24: =IF(T24*U24,Q24-P24,IF(T24>U24,人员资源情况!B$2-P24,IF(T24<U24,任务计划表!Q24-人员资源情况!A$2,0)))*R24*S24 | W24: =IF(V24<0,0,V24)
A25: 已归档 | E25: 巴西经营中心 | F25: 巴西LoRa-Walkby方案 | I25: TAG26帧修改 | J25: 固件工程师 | K25: @答金雨(80016793) | L25: 46206 | M25: 2026-07-30 | N25: 2 | O25: =任务计划表!K25 | P25: =IF(IF(任务计划表!L25="/",人员资源情况!$A$2,L25)>M25,M25,(IF(任务计划表!L25="/",人员资源情况!$A$2,L25))) | Q25: =IF(M25="/",人员资源情况!$B$2,任务计划表!M25) | R25: =任务计划表!N25 | S25: =IF(O25=人员资源情况!C$2,1,0) | T25: =IF(P25>=人员资源情况!A$2,1,0) | U25: =IF(Q25<=人员资源情况!B$2,1,0) | V25: =IF(T25*U25,Q25-P25,IF(T25>U25,人员资源情况!B$2-P25,IF(T25<U25,任务计划表!Q25-人员资源情况!A$2,0)))*R25*S25 | W25: =IF(V25<0,0,V25)
A26: 已归档 | E26: 拉美 | F26: 智利-NB | I26: 特殊-联调阶段 7月2日-系统IP申请问题，未完成联调 7月8日-预约二次联调 | J26: 固件工程师 | K26: @答金雨(80016793) | L26: / | M26: 46227 | N26: 3 | O26: =任务计划表!K26 | P26: =IF(IF(任务计划表!L26="/",人员资源情况!$A$2,L26)>M26,M26,(IF(任务计划表!L26="/",人员资源情况!$A$2,L26))) | Q26: =IF(M26="/",人员资源情况!$B$2,任务计划表!M26) | R26: =任务计划表!N26 | S26: =IF(O26=人员资源情况!C$2,1,0) | T26: =IF(P26>=人员资源情况!A$2,1,0) | U26: =IF(Q26<=人员资源情况!B$2,1,0) | V26: =IF(T26*U26,Q26-P26,IF(T26>U26,人员资源情况!B$2-P26,IF(T26<U26,任务计划表!Q26-人员资源情况!A$2,0)))*R26*S26 | W26: =IF(V26<0,0,V26)
F27: 秘鲁-CAT1 | I27: TR4A-测试阶段 | J27: 固件工程师 | K27: @答金雨(80016793) | L27: / | M27: 46223 | N27: 6 | O27: =任务计划表!K27 | P27: =IF(IF(任务计划表!L27="/",人员资源情况!$A$2,L27)>M27,M27,(IF(任务计划表!L27="/",人员资源情况!$A$2,L27))) | Q27: =IF(M27="/",人员资源情况!$B$2,任务计划表!M27) | R27: =任务计划表!N27 | S27: =IF(O27=人员资源情况!C$2,1,0) | T27: =IF(P27>=人员资源情况!A$2,1,0) | U27: =IF(Q27<=人员资源情况!B$2,1,0) | V27: =IF(T27*U27,Q27-P27,IF(T27>U27,人员资源情况!B$2-P27,IF(T27<U27,任务计划表!Q27-人员资源情况!A$2,0)))*R27*S27 | W27: =IF(V27<0,0,V27)
F28: 墨西哥MIAA | I28: TR4A-测试阶段 | J28: 项目经理 | K28: @危才文(80018808) | L28: / | M28: 46275 | N28: 0.5 | O28: =任务计划表!K28 | P28: =IF(IF(任务计划表!L28="/",人员资源情况!$A$2,L28)>M28,M28,(IF(任务计划表!L28="/",人员资源情况!$A$2,L28))) | Q28: =IF(M28="/",人员资源情况!$B$2,任务计划表!M28) | R28: =任务计划表!N28 | S28: =IF(O28=人员资源情况!C$2,1,0) | T28: =IF(P28>=人员资源情况!A$2,1,0) | U28: =IF(Q28<=人员资源情况!B$2,1,0) | V28: =IF(T28*U28,Q28-P28,IF(T28>U28,人员资源情况!B$2-P28,IF(T28<U28,任务计划表!Q28-人员资源情况!A$2,0)))*R28*S28 | W28: =IF(V28<0,0,V28)
I29: TR4A-测试阶段 | J29: 固件工程师-测试 | K29: @危才文(80018808) | L29: / | M29: 46225 | N29: 4 | O29: =任务计划表!K29 | P29: =IF(IF(任务计划表!L29="/",人员资源情况!$A$2,L29)>M29,M29,(IF(任务计划表!L29="/",人员资源情况!$A$2,L29))) | Q29: =IF(M29="/",人员资源情况!$B$2,任务计划表!M29) | R29: =任务计划表!N29 | S29: =IF(O29=人员资源情况!C$2,1,0) | T29: =IF(P29>=人员资源情况!A$2,1,0) | U29: =IF(Q29<=人员资源情况!B$2,1,0) | V29: =IF(T29*U29,Q29-P29,IF(T29>U29,人员资源情况!B$2-P29,IF(T29<U29,任务计划表!Q29-人员资源情况!A$2,0)))*R29*S29 | W29: =IF(V29<0,0,V29)
F30: 多米尼加-补货 | I30: 补充验证 | J30: 硬件工程师 | K30: @舒杰(80018942) | L30: / | M30: 46234 | N30: 6 | O30: =任务计划表!K30 | P30: =IF(IF(任务计划表!L30="/",人员资源情况!$A$2,L30)>M30,M30,(IF(任务计划表!L30="/",人员资源情况!$A$2,L30))) | Q30: =IF(M30="/",人员资源情况!$B$2,任务计划表!M30) | R30: =任务计划表!N30 | S30: =IF(O30=人员资源情况!C$2,1,0) | T30: =IF(P30>=人员资源情况!A$2,1,0) | U30: =IF(Q30<=人员资源情况!B$2,1,0) | V30: =IF(T30*U30,Q30-P30,IF(T30>U30,人员资源情况!B$2-P30,IF(T30<U30,任务计划表!Q30-人员资源情况!A$2,0)))*R30*S30 | W30: =IF(V30<0,0,V30)
F31: 哥伦比亚相关 | I31: 哥伦比亚EVB项目复测 | J31: 固件工程师 | K31: @毛文豪(80018842) | L31: 46230 | M31: 46239 | N31: 1 | O31: =任务计划表!K31 | P31: =IF(IF(任务计划表!L31="/",人员资源情况!$A$2,L31)>M31,M31,(IF(任务计划表!L31="/",人员资源情况!$A$2,L31))) | Q31: =IF(M31="/",人员资源情况!$B$2,任务计划表!M31) | R31: =任务计划表!N31 | S31: =IF(O31=人员资源情况!C$2,1,0) | T31: =IF(P31>=人员资源情况!A$2,1,0) | U31: =IF(Q31<=人员资源情况!B$2,1,0) | V31: =IF(T31*U31,Q31-P31,IF(T31>U31,人员资源情况!B$2-P31,IF(T31<U31,任务计划表!Q31-人员资源情况!A$2,0)))*R31*S31 | W31: =IF(V31<0,0,V31)
A32: 已归档 | I32: DN40-LoRaWAN测试 | J32: 固件工程师 | K32: @毛文豪(80018842) | L32: 46220 | M32: 46223 | N32: 0.8 | O32: =任务计划表!K32 | P32: =IF(IF(任务计划表!L32="/",人员资源情况!$A$2,L32)>M32,M32,(IF(任务计划表!L32="/",人员资源情况!$A$2,L32))) | Q32: =IF(M32="/",人员资源情况!$B$2,任务计划表!M32) | R32: =任务计划表!N32 | S32: =IF(O32=人员资源情况!C$2,1,0) | T32: =IF(P32>=人员资源情况!A$2,1,0) | U32: =IF(Q32<=人员资源情况!B$2,1,0) | V32: =IF(T32*U32,Q32-P32,IF(T32>U32,人员资源情况!B$2-P32,IF(T32<U32,任务计划表!Q32-人员资源情况!A$2,0)))*R32*S32 | W32: =IF(V32<0,0,V32)
E33: 欧洲 | F33: WMBUS-OMS | I33: TR4-设计开发阶段 | J33: 固件工程师 | K33: @危才文(80018808) | L33: / | M33: 46211 | N33: 6 | O33: =任务计划表!K33 | P33: =IF(IF(任务计划表!L33="/",人员资源情况!$A$2,L33)>M33,M33,(IF(任务计划表!L33="/",人员资源情况!$A$2,L33))) | Q33: =IF(M33="/",人员资源情况!$B$2,任务计划表!M33) | R33: =任务计划表!N33 | S33: =IF(O33=人员资源情况!C$2,1,0) | T33: =IF(P33>=人员资源情况!A$2,1,0) | U33: =IF(Q33<=人员资源情况!B$2,1,0) | V33: =IF(T33*U33,Q33-P33,IF(T33>U33,人员资源情况!B$2-P33,IF(T33<U33,任务计划表!Q33-人员资源情况!A$2,0)))*R33*S33 | W33: =IF(V33<0,0,V33)
F34: NB-CE | I34: 样机制作阶段 | L34: / | M34: / | O34: =任务计划表!K34 | P34: =IF(IF(任务计划表!L34="/",人员资源情况!$A$2,L34)>M34,M34,(IF(任务计划表!L34="/",人员资源情况!$A$2,L34))) | Q34: =IF(M34="/",人员资源情况!$B$2,任务计划表!M34) | R34: =任务计划表!N34 | S34: =IF(O34=人员资源情况!C$2,1,0) | T34: =IF(P34>=人员资源情况!A$2,1,0) | U34: =IF(Q34<=人员资源情况!B$2,1,0) | V34: =IF(T34*U34,Q34-P34,IF(T34>U34,人员资源情况!B$2-P34,IF(T34<U34,任务计划表!Q34-人员资源情况!A$2,0)))*R34*S34 | W34: =IF(V34<0,0,V34)
O35: =任务计划表!K35 | P35: =IF(IF(任务计划表!L35="/",人员资源情况!$A$2,L35)>M35,M35,(IF(任务计划表!L35="/",人员资源情况!$A$2,L35))) | Q35: =IF(M35="/",人员资源情况!$B$2,任务计划表!M35) | R35: =任务计划表!N35 | S35: =IF(O35=人员资源情况!C$2,1,0) | T35: =IF(P35>=人员资源情况!A$2,1,0) | U35: =IF(Q35<=人员资源情况!B$2,1,0) | V35: =IF(T35*U35,Q35-P35,IF(T35>U35,人员资源情况!B$2-P35,IF(T35<U35,任务计划表!Q35-人员资源情况!A$2,0)))*R35*S35 | W35: =IF(V35<0,0,V35)
B36: 已删除 | F36: 欧洲短款1代产品 | J36: 项目经理 | K36: @童景顺(80004217)(童景顺) | L36: / | M36: 46295 | N36: 0.5 | O36: =任务计划表!K36 | P36: =IF(IF(任务计划表!L36="/",人员资源情况!$A$2,L36)>M36,M36,(IF(任务计划表!L36="/",人员资源情况!$A$2,L36))) | Q36: =IF(M36="/",人员资源情况!$B$2,任务计划表!M36) | R36: =任务计划表!N36 | S36: =IF(O36=人员资源情况!C$2,1,0) | T36: =IF(P36>=人员资源情况!A$2,1,0) | U36: =IF(Q36<=人员资源情况!B$2,1,0) | V36: =IF(T36*U36,Q36-P36,IF(T36>U36,人员资源情况!B$2-P36,IF(T36<U36,任务计划表!Q36-人员资源情况!A$2,0)))*R36*S36 | W36: =IF(V36<0,0,V36)
B37: 已删除 | J37: 硬件设计-硬件设计文档 | K37: @童景顺(80004217)(童景顺) | L37: 46221 | M37: 46240 | N37: 2 | O37: =任务计划表!K37 | P37: =IF(IF(任务计划表!L37="/",人员资源情况!$A$2,L37)>M37,M37,(IF(任务计划表!L37="/",人员资源情况!$A$2,L37))) | Q37: =IF(M37="/",人员资源情况!$B$2,任务计划表!M37) | R37: =任务计划表!N37 | S37: =IF(O37=人员资源情况!C$2,1,0) | T37: =IF(P37>=人员资源情况!A$2,1,0) | U37: =IF(Q37<=人员资源情况!B$2,1,0) | V37: =IF(T37*U37,Q37-P37,IF(T37>U37,人员资源情况!B$2-P37,IF(T37<U37,任务计划表!Q37-人员资源情况!A$2,0)))*R37*S37 | W37: =IF(V37<0,0,V37)
B38: 已删除 | J38: 硬件工程师-PCB设计 | K38: @童景顺(80004217)(童景顺) | L38: 46242 | M38: 46245 | N38: 7 | O38: =任务计划表!K38 | P38: =IF(IF(任务计划表!L38="/",人员资源情况!$A$2,L38)>M38,M38,(IF(任务计划表!L38="/",人员资源情况!$A$2,L38))) | Q38: =IF(M38="/",人员资源情况!$B$2,任务计划表!M38) | R38: =任务计划表!N38 | S38: =IF(O38=人员资源情况!C$2,1,0) | T38: =IF(P38>=人员资源情况!A$2,1,0) | U38: =IF(Q38<=人员资源情况!B$2,1,0) | V38: =IF(T38*U38,Q38-P38,IF(T38>U38,人员资源情况!B$2-P38,IF(T38<U38,任务计划表!Q38-人员资源情况!A$2,0)))*R38*S38 | W38: =IF(V38<0,0,V38)
B39: 已删除 | J39: 固件概要设计 | K39: @项家祺(80004213)(项家祺) | L39: 46221 | M39: 46241 | N39: 2 | O39: =任务计划表!K39 | P39: =IF(IF(任务计划表!L39="/",人员资源情况!$A$2,L39)>M39,M39,(IF(任务计划表!L39="/",人员资源情况!$A$2,L39))) | Q39: =IF(M39="/",人员资源情况!$B$2,任务计划表!M39) | R39: =任务计划表!N39 | S39: =IF(O39=人员资源情况!C$2,1,0) | T39: =IF(P39>=人员资源情况!A$2,1,0) | U39: =IF(Q39<=人员资源情况!B$2,1,0) | V39: =IF(T39*U39,Q39-P39,IF(T39>U39,人员资源情况!B$2-P39,IF(T39<U39,任务计划表!Q39-人员资源情况!A$2,0)))*R39*S39 | W39: =IF(V39<0,0,V39)
B40: 已删除 | J40: 固件开发-乌拉圭版本移植 | K40: @李昊龙(80016809) | L40: 46242 | M40: 46264 | N40: 1 | O40: =任务计划表!K40 | P40: =IF(IF(任务计划表!L40="/",人员资源情况!$A$2,L40)>M40,M40,(IF(任务计划表!L40="/",人员资源情况!$A$2,L40))) | Q40: =IF(M40="/",人员资源情况!$B$2,任务计划表!M40) | R40: =任务计划表!N40 | S40: =IF(O40=人员资源情况!C$2,1,0) | T40: =IF(P40>=人员资源情况!A$2,1,0) | U40: =IF(Q40<=人员资源情况!B$2,1,0) | V40: =IF(T40*U40,Q40-P40,IF(T40>U40,人员资源情况!B$2-P40,IF(T40<U40,任务计划表!Q40-人员资源情况!A$2,0)))*R40*S40 | W40: =IF(V40<0,0,V40)
...

Sheet 操作记录
A1: 操作ID | B1: 操作时间 | C1: 操作人 | D1: 操作类型 | E1: 项目ID列表 | F1: 项目名列表 | G1: 变更前内容 | H1: 变更后内容 | I1: 状态 | J1: 关联审批ID | K1: 审批人 | L1: 审批时间
A2: OP-20260723-001 | B2: 2026-07-23T12:00:00 | C2: testuser | D2: archive | E2: [1, 2, 3] | F2: ["项目A", "项目B", "项目C"] | G2: {"状态": "active"} | H2: {"状态": "archived"} | I2: pending
A3: OP-20260723-002 | B3: 2026-07-23T13:00:00 | C3: zky | D3: edit | E3: [100] | F3: ["测试项目A"] | G3: {"负责人": "张三"} | H3: {"负责人": "李四"} | I3: cancelled | K3: zky | L3: 2026-07-23T06:24:45.243307
A4: OP-20260723-003 | B4: 2026-07-23T14:00:00 | C4: zky | D4: edit | E4: [101] | F4: ["测试撤回项目"] | G4: {"负责人": "张三"} | H4: {"负责人": "李四"} | I4: cancelled | K4: zky | L4: 2026-07-23T05:27:51.082235
A5: OP-20260723-004 | B5: 2026-07-23T15:00:00 | C5: testuser2 | D5: archive | E5: [200] | F5: ["撤回测试项目"] | I5: cancelled | K5: testuser2 | L5: 2026-07-23T05:28:49.988722
A6: OP-20260723-005 | B6: 2026-07-23T06:25:42.336944 | C6: zky | D6: archive | E6: [52] | F6: ["沙特-NB水表"] | G6: {} | H6: {} | I6: rejected | K6: xjq | L6: 2026-07-23T06:28:36.029791
A7: OP-20260723-006 | B7: 2026-07-23T06:27:17.041237 | C7: lhl | D7: archive | E7: [54] | F7: ["沙特-NB水表"] | G7: {} | H7: {} | I7: approved | K7: xjq | L7: 2026-07-23T06:28:21.733796
A8: OP-20260723-007 | B8: 2026-07-23T07:56:35.008802 | C8: mwh | D8: edit | E8: [152] | F8: ["巴勒斯坦超声户表二开"] | G8: {"资源名称": "毛文豪", "资源开始时间": "2026-07-29", "资源结束时间": "2026-07-30", "资源类型": "CIU固件代码编写", "日平均工时": 6} | H8: {"资源名称": "毛文豪", "资源开始时间": "2026-07-30", "资源结束时间": "2026-07-31", "资源类型": "CIU固件代码编写", "日平均工时": 6} | I8: approved | K8: xjq | L8: 2026-07-23T09:05:22.196252
A9: OP-20260723-008 | B9: 2026-07-23T07:58:53.007876 | C9: mwh | D9: edit | E9: [157] | F9: ["巴勒斯坦超声户表二开"] | G9: {"资源名称": "肖庆阳", "资源开始时间": "2026-08-13", "资源结束时间": "2026-08-14", "资源类型": "生产工艺及规程制定", "日平均工时": 8} | H9: {} | I9: rejected | K9: xjq | L9: 2026-07-23T10:43:17.299129
A10: OP-20260723-009 | B10: 2026-07-23T07:59:29.311253 | C10: mwh | D10: edit | E10: [155] | F10: ["巴勒斯坦超声户表二开"] | G10: {"资源名称": "袁知正", "资源开始时间": "2026-07-30", "资源结束时间": "2026-08-12", "资源类型": "测试报告", "日平均工时": 8} | H10: {"资源名称": "袁知正", "资源开始时间": "2026-07-30", "资源结束时间": "2026-08-14", "资源类型": "测试报告", "日平均工时": 8} | I10: approved | K10: xjq | L10: 2026-07-23T09:07:00.994720
A11: OP-20260723-010 | B11: 2026-07-23T08:03:07.712347 | C11: mwh | D11: archive | E11: [31] | F11: ["哥伦比亚相关"] | G11: {} | H11: {} | I11: cancelled | K11: mwh | L11: 2026-07-23T10:44:53.907149
A12: OP-20260723-011 | B12: 2026-07-23T08:03:12.506476 | C12: mwh | D12: archive | E12: [31] | F12: ["哥伦比亚相关"] | G12: {} | H12: {} | I12: approved | K12: xjq | L12: 2026-07-23T08:20:37.902251
A13: OP-20260723-012 | B13: 2026-07-23T09:11:06.675414 | C13: mwh | D13: edit | E13: [155] | F13: ["巴勒斯坦超声户表二开"] | G13: {"资源名称": "袁知正", "资源开始时间": "2026-07-30", "资源结束时间": "2026-08-14", "资源类型": "测试报告", "日平均工时": 8} | H13: {"资源名称": "袁知正", "资源开始时间": "2026-07-30", "资源结束时间": "2026-08-05", "资源类型": "第一轮测试", "日平均工时": 8} | I13: approved | K13: xjq | L13: 2026-07-23T09:16:57.270975
A14: OP-20260723-013 | B14: 2026-07-23T09:11:38.074728 | C14: mwh | D14: edit | E14: [153] | F14: ["巴勒斯坦超声户表二开"] | G14: {"资源名称": "文春英", "资源开始时间": "2026-07-30", "资源结束时间": "2026-08-03", "资源类型": "样机制作", "日平均工时": 2} | H14: {"资源名称": "文春英", "资源开始时间": "2026-07-28", "资源结束时间": "2026-08-30", "资源类型": "样机制作", "日平均工时": 2} | I14: approved | K14: xjq | L14: 2026-07-23T09:16:29.173013
A15: OP-20260723-014 | B15: 2026-07-23T09:13:28.712841 | C15: mwh | D15: add | E15: [] | F15: ["巴勒斯坦超声户表二开"] | G15: {} | H15: {"部门": "亚洲", "项目": "巴勒斯坦超声户表二开", "项目开始时间": "1900-01-01", "项目结束时间": "2100-01-01", "项目描述": "第二轮测试", "资源类型": "测试工程师", "资源名称": "袁知正", "资源开始时间": "2026-08-07", "资源结束时间": "2026-08-13", "日平均工时": 8, "已归档": false} | I15: approved | K15: xjq | L15: 2026-07-23T09:16:01.868320
A16: OP-20260723-015 | B16: 2026-07-23T09:31:29.791935 | C16: mwh | D16: archive | E16: [49] | F16: ["巴勒斯坦-LoRa"] | G16: {} | H16: {} | I16: cancelled | K16: mwh | L16: 2026-07-23T10:44:27.799263
A17: OP-20260723-016 | B17: 2026-07-23T09:31:51.500903 | C17: mwh | D17: edit | E17: [153] | F17: ["巴勒斯坦超声户表二开"] | G17: {"部门": "亚洲", "项目": "巴勒斯坦超声户表二开", "项目描述": "TR4A", "资源类型": "样机制作", "资源名称": "文春英", "资源开始时间": "2026-07-28", "资源结束时间": "2026-08-30", "日平均工时": 2} | H17: {"部门": "亚洲", "项目": "巴勒斯坦超声户表二开", "项目描述": "TR4A", "资源类型": "样机制作", "资源名称": "文春英", "资源开始时间": "2026-07-28", "资源结束时间": "2026-07-30", "日平均工时": 2} | I17: cancelled | K17: mwh | L17: 2026-07-23T10:44:38.898072
... A26: OP-20260724-002 | B26: 2026-07-24T12:45:03.385353 | C26: dajinyu | D26: archive | E26: [24] | F26: ["巴西LoRa-Walkby方案"] | G26: {"部门": "巴西经营中心", "项目": "巴西LoRa-Walkby方案", "项目描述": "TAG26帧修改", "资源类型": "固件工程师", "资源名称": "答金雨", "资源开始时间": "2026-07-03", "资源结束时间": "2026-07-30", "日平均工时": 2} | H26: {} | I26: approved | K26: xjq | L26: 2026-07-24T12:46:10.975588
A27: OP-20260725-001 | B27: 2026-07-25T07:14:52.533144 | C27: xjq | D27: requirement_submit | E27: [] | F27: ["测试需求"] | G27: {} | H27: {"status": "submitted"} | I27: direct
A28: OP-20260727-001 | B28: 2026-07-27T00:21:57.938181 | C28: xjq | D28: requirement_submit | E28: [] | F28: ["测试需求"] | G28: {} | H28: {"status": "submitted"} | I28: direct
A29: OP-20260727-002 | B29: 2026-07-27T00:22:16.731376 | C29: xjq | D29: requirement_reject | E29: [] | F29: ["测试需求"] | G29: {"status": "submitted"} | H29: {"status": "deleted", "拒绝原因": "测试拒绝"} | I29: direct
A30: OP-20260727-003 | B30: 2026-07-27T00:23:49.827749 | C30: xjq | D30: requirement_delete | E30: [] | F30: ["[已删除]"] | G30: {"status": "deleted"} | H30: {"status": "deleted"} | I30: direct
A31: OP-20260727-004 | B31: 2026-07-27T00:24:14.038420 | C31: xjq-cs | D31: requirement_submit | E31: [] | F31: ["测试需求-2"] | G31: {} | H31: {"status": "submitted"} | I31: direct
A32: OP-20260727-005 | B32: 2026-07-27T00:25:46.738610 | C32: xjq-cs | D32: archive | E32: [216] | F32: ["TEST demand"] | G32: {"部门": "测试", "项目": "TEST demand", "项目描述": "新增", "资源类型": "项目经理", "资源名称": "项家祺", "资源开始时间": "2026-07-25", "资源结束时间": "2026-07-25", "日平均工时": 8} | H32: {} | I32: approved | K32: xjq | L32: 2026-07-27T00:29:26.126991
A33: OP-20260727-006 | B33: 2026-07-27T00:26:10.833371 | C33: xjq-cs | D33: archive | E33: [217] | F33: ["TEST demand"] | G33: {"部门": "测试", "项目": "TEST demand", "项目描述": "2", "资源类型": "项目CHAT", "资源名称": "项家祺", "资源开始时间": "2026-07-25", "资源结束时间": "2026-07-25", "日平均工时": 8} | H33: {} | I33: approved | K33: xjq | L33: 2026-07-27T00:28:46.528678
A34: OP-20260727-007 | B34: 2026-07-27T00:27:06.735835 | C34: xjq | D34: requirement_link_projects | E34: [] | F34: ["测试需求-2"] | G34: {"linked_projects": ["测试看板"]} | H34: {"linked_projects": ["测试看板"]} | I34: direct
A35: OP-20260727-008 | B35: 2026-07-27T05:40:52.435980 | C35: xjq | D35: requirement_submit | E35: [] | F35: ["测试需求看板"] | G35: {} | H35: {"status": "submitted"} | I35: direct
A36: OP-20260727-009 | B36: 2026-07-27T05:41:11.752094 | C36: xjq | D36: requirement_link_projects | E36: [] | F36: ["测试需求看板"] | G36: {"linked_projects": []} | H36: {"linked_projects": ["测试看板"]} | I36: direct
A37: OP-20260727-010 | B37: 2026-07-27T05:41:16.125646 | C37: xjq | D37: requirement_accept | E37: [] | F37: ["测试需求看板"] | G37: {"status": "submitted"} | H37: {"status": "accepted"} | I37: direct
A38: OP-20260727-011 | B38: 2026-07-27T05:50:34.312709 | C38: xjq | D38: requirement_archive | E38: [] | F38: ["测试需求看板"] | G38: {"status": "accepted"} | H38: {"status": "archived"} | I38: direct
A39: OP-20260727-012 | B39: 2026-07-27T05:52:01.700756 | C39: xjq | D39: requirement_submit | E39: [] | F39: ["测试需求看板"] | G39: {} | H39: {"status": "submitted"} | I39: direct
A40: OP-20260727-013 | B40: 2026-07-27T05:52:14.517231 | C40: xjq | D40: requirement_delete | E40: [] | F40: ["[已删除]"] | G40: {"status": "submitted"} | H40: {"status": "deleted"} | I40: direct
A41: OP-20260727-014 | B41: 2026-07-27T05:53:09.419108 | C41: xjq | D41: requirement_delete | E41: [] | F41: ["[已删除]"] | G41: {"status": "deleted"} | H41: {"status": "deleted"} | I41: direct
A42: OP-20260727-015 | B42: 2026-07-27T05:54:36.691535 | C42: xjq | D42: requirement_reject | E42: [] | F42: ["测试需求看板"] | G42: {"status": "archived"} | H42: {"status": "submitted", "拒绝原因": "1234"} | I42: direct
A43: OP-20260727-016 | B43: 2026-07-27T05:54:48.728277 | C43: xjq | D43: requirement_reject | E43: [] | F43: ["测试需求看板"] | G43: {"status": "submitted"} | H43: {"status": "deleted", "拒绝原因": "123"} | I43: direct
A44: OP-20260727-017 | B44: 2026-07-27T06:04:41.301748 | C44: xjq-cs | D44: archive | E44: [149] | F44: ["巴勒斯坦超声户表二开"] | G44: {"部门": "亚洲", "项目": "巴勒斯坦超声户表二开", "项目描述": "TR3", "资源类型": "巴勒斯坦二开SE文档评审", "资源名称": "毛文豪", "资源开始时间": "2026-07-21", "资源结束时间": "2026-07-23", "日平均工时": 8} | H44: {} | I44: approved | K44: xjq | L44: 2026-07-27T06:05:42.595540
A45: OP-20260728-001 | B45: 2026-07-28T01:33:47.088262 | C45: wyh | D45: edit | E45: [52] | F45: ["沙特-NB水表"] | G45: {"部门": "中东", "项目": "沙特-NB水表", "项目描述": "预研阶段", "资源类型": "固件工程师-压力传感器学习", "资源名称": "魏殷浩", "资源开始时间": "2026-07-07", "资源结束时间": "2026-07-10", "日平均工时": 6} | H45: {"部门": "中东", "项目": "沙特-NB水表", "项目描述": "预研阶段", "资源类型": "固件工程师-压力传感器I2C功能测试", "资源名称": "魏殷浩", "资源开始时间": "2026-07-28", "资源结束时间": "2026-07-31", "日平均工时": 6} | I45: pending
A46: OP-20260728-002 | B46: 2026-07-28T01:34:29.490633 | C46: wyh | D46: edit | E46: [53] | F46: ["沙特-NB水表"] | G46: {"部门": "中东", "项目": "沙特-NB水表", "项目描述": "预研阶段", "资源类型": "固件工程师-压力传感器驱动开发", "资源名称": "魏殷浩", "资源开始时间": "2026-07-20", "资源结束时间": "2026-07-31", "日平均工时": 7} | H46: {"部门": "中东", "项目": "沙特-NB水表", "项目描述": "预研阶段", "资源类型": "固件工程师-压力传感器驱动开发", "资源名称": "魏殷浩", "资源开始时间": "2026-08-01", "资源结束时间": "2026-08-20", "日平均工时": 7} | I46: pending
A47: OP-20260728-003 | B47: 2026-07-28T02:02:20.086050 | C47: wyh | D47: edit | E47: [52] | F47: ["沙特-NB水表"] | G47: {"部门": "中东", "项目": "沙特-NB水表", "项目描述": "预研阶段", "资源类型": "固件工程师-压力传感器学习", "资源名称": "魏殷浩", "资源开始时间": "2026-07-07", "资源结束时间": "2026-07-10", "日平均工时": 6} | H47: {"部门": "中东", "项目": "沙特-NB水表", "项目描述": "预研阶段", "资源类型": "固件工程师-压力传感器功能测试", "资源名称": "魏殷浩", "资源开始时间": "2026-07-28", "资源结束时间": "2026-07-31", "日平均工时": 6} | I47: approved | K47: xjq | L47: 2026-07-28T07:34:30.383344
A48: OP-20260728-004 | B48: 2026-07-28T02:03:08.087594 | C48: wyh | D48: edit | E48: [53] | F48: ["沙特-NB水表"] | G48: {"部门": "中东", "项目": "沙特-NB水表", "项目描述": "预研阶段", "资源类型": "固件工程师-压力传感器驱动开发", "资源名称": "魏殷浩", "资源开始时间": "2026-07-20", "资源结束时间": "2026-07-31", "日平均工时": 7} | H48: {"部门": "中东", "项目": "沙特-NB水表", "项目描述": "预研阶段", "资源类型": "固件工程师-压力传感器驱动开发", "资源名称": "魏殷浩", "资源开始时间": "2026-08-01", "资源结束时间": "2026-08-20", "日平均工时": 7} | I48: approved | K48: xjq | L48: 2026-07-28T07:35:04.781010
